<?xml version="1.0" ?>
<!-- =================================================================================== -->
<!-- |    This document was autogenerated by xacro from my_first_application.xacro     | -->
<!-- |    EDITING THIS FILE BY HAND IS NOT RECOMMENDED                                 | -->
<!-- =================================================================================== -->
<robot name="prbt" xmlns:xacro="http://www.ros.org/wiki/xacro">
  <!-- coloring from the stl file -->
  <material name="yellow">
    <color rgba="1 1 0 1"/>
  </material>
  <!-- coloring from the table -->
  <material name="grey">
    <color rgba="0.75 0.75 0.75 1"/>
  </material>
  <!-- robot foot link -->
  <link name="prbt_base_link">
    <inertial>
      <mass value="2.4"/>
      <inertia ixx="0" ixy="0" ixz="0" iyy="0" iyz="0" izz="0"/>
    </inertial>
    <visual>
      <origin rpy="0 0 0" xyz="0 0 0"/>
      <geometry>
        <mesh filename="package://prbt_support/meshes/foot.dae"/>
      </geometry>
    </visual>
    <collision>
      <origin rpy="3.14159265359 0 0" xyz="0 0 0.065"/>
      <geometry>
        <cylinder length="0.13" radius="0.09275"/>
      </geometry>
    </collision>
  </link>
  <!-- arm 1 joint -->
  <joint name="prbt_joint_1" type="revolute">
    <origin rpy="0 0 -3.14159265359" xyz="0 0 0.2604"/>
    <parent link="prbt_base_link"/>
    <child link="prbt_link_1"/>
    <axis xyz="0 0 1"/>
    <limit effort="370" lower="-2.967" upper="2.967" velocity="1.57"/>
    <dynamics damping="15.0" friction="11"/>
  </joint>
  <!-- arm 1 link -->
  <link name="prbt_link_1">
    <inertial>
      <mass value="7.1"/>
      <origin xyz="0 -0.026 -0.051"/>
      <inertia ixx="3.53e-2" ixy="0" ixz="0" iyy="3.01e-2" iyz="9.04e-3" izz="1.87e-2"/>
    </inertial>
    <visual>
      <origin rpy="0 0 0" xyz="0 0 0"/>
      <geometry>
        <mesh filename="package://prbt_support/meshes/link_1.dae"/>
      </geometry>
    </visual>
    <collision>
      <origin rpy="0 0 0" xyz="0 0 -0.08"/>
      <geometry>
        <cylinder length="0.10" radius="0.07"/>
      </geometry>
    </collision>
    <collision>
      <origin rpy="0 0 0" xyz="0 0 0"/>
      <geometry>
        <sphere radius="0.09"/>
      </geometry>
    </collision>
    <collision>
      <origin rpy="0 1.57079632679 1.57079632679" xyz="0 -0.10 0"/>
      <geometry>
        <cylinder length="0.10" radius="0.065"/>
      </geometry>
    </collision>
  </link>
  <!-- joint between arm_1_link and arm_2_link -->
  <joint name="prbt_joint_2" type="revolute">
    <origin rpy="1.57079632679 0 0" xyz="0 0 0"/>
    <parent link="prbt_link_1"/>
    <child link="prbt_link_2"/>
    <axis xyz="0 0 1"/>
    <limit effort="370" lower="-2.531" upper="2.531" velocity="1.57"/>
    <dynamics damping="12.0" friction="10.0"/>
  </joint>
  <link name="prbt_link_2">
    <inertial>
      <mass value="1.7"/>
      <origin xyz="0 0.162 0.134"/>
      <inertia ixx="3.58e-2" ixy="0" ixz="0" iyy="3.22e-3" iyz="-1.45e-3" izz="3.66e-2"/>
    </inertial>
    <visual name="first">
      <origin rpy="0 0 0" xyz="0 0 0"/>
      <geometry>
        <mesh filename="package://prbt_support/meshes/link_2.dae"/>
      </geometry>
    </visual>
    <collision>
      <origin rpy="0.174532925199 0 0" xyz="0 0.15 0.145"/>
      <geometry>
        <box size="0.121 0.27 0.065"/>
      </geometry>
    </collision>
    <collision>
      <origin rpy="-0.448798950513 0 0" xyz="0 0.3 0.145"/>
      <geometry>
        <box size="0.11 0.1 0.075"/>
      </geometry>
    </collision>
  </link>
  <!-- joint between arm_2_link and arm_3_link -->
  <joint name="prbt_joint_3" type="revolute">
    <origin rpy="0 3.14159265359 0" xyz="0 0.35 0"/>
    <parent link="prbt_link_2"/>
    <child link="prbt_link_3"/>
    <axis xyz="0 0 1"/>
    <limit effort="176" lower="-2.356" upper="2.356" velocity="1.57"/>
    <dynamics damping="4.5" friction="4.5"/>
  </joint>
  <link name="prbt_link_3">
    <inertial>
      <mass value="4.8"/>
      <origin xyz="0 0.043 -0.027"/>
      <inertia ixx="2.06e-2" ixy="0" ixz="0" iyy="1.08e-2" iyz="-5.36e-3" izz="1.63e-2"/>
    </inertial>
    <visual>
      <origin rpy="0 0 0" xyz="0 0 0"/>
      <geometry>
        <mesh filename="package://prbt_support/meshes/link_3.dae"/>
      </geometry>
    </visual>
    <collision>
      <origin rpy="0 0 0" xyz="0 0 -0.11"/>
      <geometry>
        <cylinder length="0.10" radius="0.06"/>
      </geometry>
    </collision>
    <collision>
      <origin rpy="0 0 0" xyz="0 0 0"/>
      <geometry>
        <sphere radius="0.085"/>
      </geometry>
    </collision>
    <collision>
      <origin rpy="0 1.57079632679 1.57079632679" xyz="0 0.10 0"/>
      <geometry>
        <cylinder length="0.10" radius="0.065"/>
      </geometry>
    </collision>
  </link>
  <!-- joint between arm_3_link and arm_4_link -->
  <joint name="prbt_joint_4" type="revolute">
    <origin rpy="-1.57079632679 3.14159265359 0" xyz="0 0 0"/>
    <parent link="prbt_link_3"/>
    <child link="prbt_link_4"/>
    <axis xyz="0 0 1"/>
    <limit effort="176" lower="-2.967" upper="2.967" velocity="1.57"/>
    <dynamics damping="4.2" friction="3.8"/>
  </joint>
  <link name="prbt_link_4">
    <inertial>
      <mass value="0.9"/>
      <origin xyz="0 -0.061 0.204"/>
      <inertia ixx="6.79e-3" ixy="0" ixz="0" iyy="4.91e-3" iyz="2.67e-3" izz="3.40e-3"/>
    </inertial>
    <visual>
      <origin rpy="0 0 0" xyz="0 0 0"/>
      <geometry>
        <mesh filename="package://prbt_support/meshes/link_4.dae"/>
      </geometry>
    </visual>
    <collision>
      <origin rpy="0.966643893412 0 0" xyz="0 -0.04 0.162"/>
      <geometry>
        <box size="0.121 0.08 0.17"/>
      </geometry>
    </collision>
    <collision>
      <origin rpy="-0.10471975512 0 0" xyz="0 -0.115 0.25"/>
      <geometry>
        <box size="0.09 0.06 0.12"/>
      </geometry>
    </collision>
  </link>
  <!-- joint between arm_4_link and arm_5_link -->
  <joint name="prbt_joint_5" type="revolute">
    <origin rpy="1.57079632679 0 3.14159265359" xyz="0 0 0.307"/>
    <parent link="prbt_link_4"/>
    <child link="prbt_link_5"/>
    <axis xyz="0 0 1"/>
    <limit effort="41.6" lower="-2.967" upper="2.967" velocity="1.57"/>
    <dynamics damping="1.5" friction="3.5"/>
  </joint>
  <link name="prbt_link_5">
    <inertial>
      <mass value="2.6"/>
      <origin xyz="-0.001 0.021 -0.032"/>
      <inertia ixx="7.37e-3" ixy="4.78e-6" ixz="6.00e-5" iyy="5.87e-3" iyz="-1.71e-3" izz="3.96e-3"/>
    </inertial>
    <visual>
      <origin rpy="0 0 0" xyz="0 0 0"/>
      <geometry>
        <mesh filename="package://prbt_support/meshes/link_5.dae"/>
      </geometry>
    </visual>
    <collision>
      <origin rpy="0 0 0" xyz="0 0 -0.095"/>
      <geometry>
        <cylinder length="0.08" radius="0.045"/>
      </geometry>
    </collision>
    <collision>
      <origin rpy="0 0 0" xyz="0 0 -0.06"/>
      <geometry>
        <cylinder length="0.04" radius="0.0545"/>
      </geometry>
    </collision>
    <collision>
      <origin rpy="0 0 0" xyz="0 0 0"/>
      <geometry>
        <sphere radius="0.07"/>
      </geometry>
    </collision>
    <collision>
      <origin rpy="0 1.57079632679 1.57079632679" xyz="0 0.05 0"/>
      <geometry>
        <cylinder length="0.03" radius="0.05"/>
      </geometry>
    </collision>
    <collision>
      <origin rpy="0 1.57079632679 1.57079632679" xyz="0 0.05 0"/>
      <geometry>
        <cylinder length="0.049" radius="0.0435"/>
      </geometry>
    </collision>
  </link>
  <!-- joint between arm_5_link and flange -->
  <joint name="prbt_joint_6" type="revolute">
    <origin rpy="-1.57079632679 0 0" xyz="0 0.084 0"/>
    <parent link="prbt_link_5"/>
    <child link="prbt_flange"/>
    <axis xyz="0 0 1"/>
    <limit effort="20.1" lower="-3.124" upper="3.124" velocity="1.57"/>
    <dynamics damping="4.5" friction="7.0"/>
  </joint>
  <!-- Flange -->
  <link name="prbt_flange">
    <inertial>
      <mass value="0.02"/>
      <origin xyz="0 0 0"/>
      <inertia ixx="0" ixy="0" ixz="0" iyy="0" iyz="0" izz="0"/>
    </inertial>
    <visual>
      <origin rpy="0 0 0" xyz="0 0 0"/>
      <geometry>
        <mesh filename="package://prbt_support/meshes/flange.dae"/>
      </geometry>
    </visual>
    <collision>
      <origin rpy="0 0 0" xyz="0 0 -0.0035"/>
      <geometry>
        <cylinder length="0.02" radius="0.0331"/>
      </geometry>
    </collision>
  </link>
  <!-- ROS-Industrial 'base' frame: base_link to robot world coordinate sytem transform -->
  <link name="prbt_base"/>
  <joint name="prbt_base_link-base" type="fixed">
    <origin rpy="0 0 0" xyz="0 0 0"/>
    <parent link="prbt_base_link"/>
    <child link="prbt_base"/>
  </joint>
  <!-- ROS-Industrial 'tool0' frame: all-zeros tool frame -->
  <link name="prbt_tool0"/>
  <joint name="prbt_flange-tool0" type="fixed">
    <origin rpy="0 0 0" xyz="0 0 0"/>
    <parent link="prbt_flange"/>
    <child link="prbt_tool0"/>
  </joint>
  <!-- transmissions for gazebo -->
  <transmission name="prbt_joint_1_trans">
    <type>transmission_interface/SimpleTransmission</type>
    <joint name="prbt_joint_1">
      <hardwareInterface>hardware_interface/PositionJointInterface</hardwareInterface>
    </joint>
    <actuator name="prbt_joint_1_motor"/>
  </transmission>
  <transmission name="prbt_joint_2_trans">
    <type>transmission_interface/SimpleTransmission</type>
    <joint name="prbt_joint_2">
      <hardwareInterface>hardware_interface/PositionJointInterface</hardwareInterface>
    </joint>
    <actuator name="prbt_joint_2_motor"/>
  </transmission>
  <transmission name="prbt_joint_3_trans">
    <type>transmission_interface/SimpleTransmission</type>
    <joint name="prbt_joint_3">
      <hardwareInterface>hardware_interface/PositionJointInterface</hardwareInterface>
    </joint>
    <actuator name="prbt_joint_3_motor"/>
  </transmission>
  <transmission name="prbt_joint_4_trans">
    <type>transmission_interface/SimpleTransmission</type>
    <joint name="prbt_joint_4">
      <hardwareInterface>hardware_interface/PositionJointInterface</hardwareInterface>
    </joint>
    <actuator name="prbt_joint_4_motor"/>
  </transmission>
  <transmission name="prbt_joint_5_trans">
    <type>transmission_interface/SimpleTransmission</type>
    <joint name="prbt_joint_5">
      <hardwareInterface>hardware_interface/PositionJointInterface</hardwareInterface>
    </joint>
    <actuator name="prbt_joint_5_motor"/>
  </transmission>
  <transmission name="prbt_joint_6_trans">
    <type>transmission_interface/SimpleTransmission</type>
    <joint name="prbt_joint_6">
      <hardwareInterface>hardware_interface/PositionJointInterface</hardwareInterface>
    </joint>
    <actuator name="prbt_joint_6_motor"/>
  </transmission>
  <gazebo>
    <plugin filename="libgazebo_ros_control.so" name="gazebo_ros_control">
      <robotNamespace>prbt</robotNamespace>
    </plugin>
  </gazebo>
  <link name="table">
    <visual>
      <origin rpy="0 0 0" xyz="0 0 -0.03"/>
      <geometry>
        <box size="0.6 1.2 0.05"/>
      </geometry>
      <material name="grey"/>
    </visual>
  </link>
  <link name="pnoz">
    <visual>
      <origin rpy="1.5708 0 0" xyz="0 -0.5 0"/>
      <geometry>
        <mesh filename="package://pilz_tutorial/urdf/meshes/PNOZ.stl" scale="0.001 0.001 0.001"/>
      </geometry>
      <material name="yellow"/>
    </visual>
  </link>
  <!-- Add the tcp (tutorial 2) -->
  <link name="prbt_tcp"/>
  <joint name="table_joint" type="fixed">
    <parent link="table"/>
    <child link="prbt_base_link"/>
  </joint>
  <joint name="pnoz_joint" type="fixed">
    <parent link="table"/>
    <child link="pnoz"/>
  </joint>
  <!-- connect the added tcp and the flange with a joint (tutorial 2)-->
  <joint name="prbt_fixed_joint_tcp" type="fixed">
    <origin rpy="0 0 0" xyz="0 0 0.05"/>
    <parent link="prbt_flange"/>
    <child link="prbt_tcp"/>
  </joint>
</robot>
